Workbook

Sheet 00_Overview
A1: University Travel - Survey & Business-Trip Data Collection
A2: ILLUSTRATIVE PORTFOLIO SAMPLE: synthetic data for demonstration
A4: Purpose | B4: Shows how the two travel activities a university actually needs to estimate, everyday staff/student commuting (no booking system exists for this) and business travel (which does have a booking trail) are built up from primary data rather than assumed.
A6: Method
A7: 1. Commuting questionnaire : a short survey (tab 01) is circulated to staff and students. It captures categorical, easy-to-answer information (a distance band, a usual mode, days on campus) rather than exact km, because that is what people can answer accurately.
A8: 2. Survey responses : raw, respondent-level answers are logged as-is (tab 02). This is qualitative/categorical data: nothing is calculated yet.
A9: 3. Interpretation into assumptions : tab 03 turns the categorical answers into quantitative assumptions (mode share %, average one-way km per mode, average days/week per mode) using a transparent distance-band lookup.
A10: 4. Business-trip bookings : the university's actual travel-booking export (tab 04): one row per trip, with destination, date and mode. Distance is looked up from a destination table, not estimated.
A11: 5. Monthly aggregation : tab 05 rolls the raw bookings up into monthly totals by mode. Tab 06 turns the commuting assumptions into a monthly estimate by applying them to each month's occupied FTE (so vacation months automatically show less commuting).
A12: 6. Combined monthly activity : tab 07 merges both monthly tables into one activity dataset in the same shape as the main travel-analysis workbook's Raw Data tab, ready to carry emission factors.
A13: 7. Emissions & KPIs : tab 08 holds the factors, tab 09 the resulting KPIs and dashboard.

Sheet 01_Commuting Questionnaire
A1: Staff & Student Commuting Survey
A2: ~3 minutes · anonymous · used only to estimate typical commuting patterns for sustainability reporting
A4: Q1 | B4: Are you staff or a student?
B5: Options: Staff / Student
A7: Q2 | B7: Roughly how far is your home from campus (one way)?
B8: Options: <2 km / 2–5 km / 5–10 km / 10–20 km / >20 km
A10: Q3 | B10: What is your usual way of getting to campus?
B11: Options: Walk or cycle / Public transport / Car (drive alone) / Car share / Mixed — depends on day
A13: Q4 | B13: On a typical week, how many days do you come to campus?
B14: Options: 1 / 2 / 3 / 4 / 5
A16: Q5 | B16: Anything that affects your travel choice seasonally? (optional)
B17: Options: Free text, e.g. "cycles in summer, bus in winter"
A20: Note: distance bands and mode categories (not exact km) are deliberately used — this is what respondents can answer reliably; km-level assumptions are derived afterwards, transparently, in tab 03.

Sheet 02_Commuting Survey Responses
A1: Respondent ID | B1: Role | C1: Home distance band | D1: Usual commute mode | E1: Days on campus/week | F1: Notes | G1: Est. one-way km
A2: 1 | B2: Staff | C2: 10-20 km | D2: Walk or cycle | E2: 4 | G2: =INDEX('03_Commuting Assumptions'!$B$3:$B$7,MATCH(C2,'03_Commuting Assumptions'!$A$3:$A$7,0)) -> 15
A3: 2 | B3: Staff | C3: 10-20 km | D3: Car (drive alone) | E3: 5 | G3: =INDEX('03_Commuting Assumptions'!$B$3:$B$7,MATCH(C3,'03_Commuting Assumptions'!$A$3:$A$7,0)) -> 15
A4: 3 | B4: Staff | C4: <2 km | D4: Car (drive alone) | E4: 2 | G4: =INDEX('03_Commuting Assumptions'!$B$3:$B$7,MATCH(C4,'03_Commuting Assumptions'!$A$3:$A$7,0)) -> 1
A5: 4 | B5: Staff | C5: 2-5 km | D5: Car (drive alone) | E5: 2 | G5: =INDEX('03_Commuting Assumptions'!$B$3:$B$7,MATCH(C5,'03_Commuting Assumptions'!$A$3:$A$7,0)) -> 3.5
A6: 5 | B6: Staff | C6: 2-5 km | D6: Car (drive alone) | E6: 4 | G6: =INDEX('03_Commuting Assumptions'!$B$3:$B$7,MATCH(C6,'03_Commuting Assumptions'!$A$3:$A$7,0)) -> 3.5
A7: 6 | B7: Staff | C7: 2-5 km | D7: Car (drive alone) | E7: 5 | G7: =INDEX('03_Commuting Assumptions'!$B$3:$B$7,MATCH(C7,'03_Commuting Assumptions'!$A$3:$A$7,0)) -> 3.5
A8: 7 | B8: Staff | C8: <2 km | D8: Car share | E8: 5 | G8: =INDEX('03_Commuting Assumptions'!$B$3:$B$7,MATCH(C8,'03_Commuting Assumptions'!$A$3:$A$7,0)) -> 1
A9: 8 | B9: Staff | C9: 5-10 km | D9: Public transport | E9: 5 | G9: =INDEX('03_Commuting Assumptions'!$B$3:$B$7,MATCH(C9,'03_Commuting Assumptions'!$A$3:$A$7,0)) -> 7.5
A10: 9 | B10: Staff | C10: 5-10 km | D10: Walk or cycle | E10: 2 | G10: =INDEX('03_Commuting Assumptions'!$B$3:$B$7,MATCH(C10,'03_Commuting Assumptions'!$A$3:$A$7,0)) -> 7.5
A11: 10 | B11: Staff | C11: 10-20 km | D11: Car share | E11: 5 | G11: =INDEX('03_Commuting Assumptions'!$B$3:$B$7,MATCH(C11,'03_Commuting Assumptions'!$A$3:$A$7,0)) -> 15
A12: 11 | B12: Staff | C12: 5-10 km | D12: Mixed | E12: 4 | F12: Cycles in summer, public transport in winter | G12: =INDEX('03_Commuting Assumptions'!$B$3:$B$7,MATCH(C12,'03_Commuting Assumptions'!$A$3:$A$7,0)) -> 7.5
A13: 12 | B13: Staff | C13: >20 km | D13: Car (drive alone) | E13: 5 | G13: =INDEX('03_Commuting Assumptions'!$B$3:$B$7,MATCH(C13,'03_Commuting Assumptions'!$A$3:$A$7,0)) -> 25
A14: 13 | B14: Staff | C14: 10-20 km | D14: Car share | E14: 2 | G14: =INDEX('03_Commuting Assumptions'!$B$3:$B$7,MATCH(C14,'03_Commuting Assumptions'!$A$3:$A$7,0)) -> 15
A15: 14 | B15: Staff | C15: 2-5 km | D15: Public transport | E15: 2 | G15: =INDEX('03_Commuting Assumptions'!$B$3:$B$7,MATCH(C15,'03_Commuting Assumptions'!$A$3:$A$7,0)) -> 3.5
A16: 15 | B16: Staff | C16: 2-5 km | D16: Public transport | E16: 4 | G16: =INDEX('03_Commuting Assumptions'!$B$3:$B$7,MATCH(C16,'03_Commuting Assumptions'!$A$3:$A$7,0)) -> 3.5
A17: 16 | B17: Staff | C17: 10-20 km | D17: Car (drive alone) | E17: 4 | G17: =INDEX('03_Commuting Assumptions'!$B$3:$B$7,MATCH(C17,'03_Commuting Assumptions'!$A$3:$A$7,0)) -> 15
A18: 17 | B18: Student | C18: <2 km | D18: Walk or cycle | E18: 5 | G18: =INDEX('03_Commuting Assumptions'!$B$3:$B$7,MATCH(C18,'03_Commuting Assumptions'!$A$3:$A$7,0)) -> 1
A19: 18 | B19: Student | C19: 2-5 km | D19: Walk or cycle | E19: 4 | F19: Drives when raining heavily | G19: =INDEX('03_Commuting Assumptions'!$B$3:$B$7,MATCH(C19,'03_Commuting Assumptions'!$A$3:$A$7,0)) -> 3.5
A20: 19 | B20: Student | C20: 2-5 km | D20: Mixed | E20: 4 | F20: Cycles in summer, public transport in winter | G20: =INDEX('03_Commuting Assumptions'!$B$3:$B$7,MATCH(C20,'03_Commuting Assumptions'!$A$3:$A$7,0)) -> 3.5
A21: 20 | B21: Student | C21: 5-10 km | D21: Car (drive alone) | E21: 4 | G21: =INDEX('03_Commuting Assumptions'!$B$3:$B$7,MATCH(C21,'03_Commuting Assumptions'!$A$3:$A$7,0)) -> 7.5
A22: 21 | B22: Student | C22: <2 km | D22: Walk or cycle | E22: 3 | G22: =INDEX('03_Commuting Assumptions'!$B$3:$B$7,MATCH(C22,'03_Commuting Assumptions'!$A$3:$A$7,0)) -> 1
A23: 22 | B23: Student | C23: <2 km | D23: Mixed | E23: 5 | F23: Cycles in summer, public transport in winter | G23: =INDEX('03_Commuting Assumptions'!$B$3:$B$7,MATCH(C23,'03_Commuting Assumptions'!$A$3:$A$7,0)) -> 1
A24: 23 | B24: Student | C24: 5-10 km | D24: Walk or cycle | E24: 5 | G24: =INDEX('03_Commuting Assumptions'!$B$3:$B$7,MATCH(C24,'03_Commuting Assumptions'!$A$3:$A$7,0)) -> 7.5
A25: 24 | B25: Student | C25: <2 km | D25: Walk or cycle | E25: 4 | G25: =INDEX('03_Commuting Assumptions'!$B$3:$B$7,MATCH(C25,'03_Commuting Assumptions'!$A$3:$A$7,0)) -> 1
A26: 25 | B26: Student | C26: 2-5 km | D26: Car share | E26: 3 | G26: =INDEX('03_Commuting Assumptions'!$B$3:$B$7,MATCH(C26,'03_Commuting Assumptions'!$A$3:$A$7,0)) -> 3.5
A27: 26 | B27: Student | C27: <2 km | D27: Mixed | E27: 4 | F27: Cycles in summer, public transport in winter | G27: =INDEX('03_Commuting Assumptions'!$B$3:$B$7,MATCH(C27,'03_Commuting Assumptions'!$A$3:$A$7,0)) -> 1
A28: 27 | B28: Student | C28: <2 km | D28: Walk or cycle | E28: 4 | G28: =INDEX('03_Commuting Assumptions'!$B$3:$B$7,MATCH(C28,'03_Commuting Assumptions'!$A$3:$A$7,0)) -> 1
A29: 28 | B29: Student | C29: 2-5 km | D29: Walk or cycle | E29: 3 | G29: =INDEX('03_Commuting Assumptions'!$B$3:$B$7,MATCH(C29,'03_Commuting Assumptions'!$A$3:$A$7,0)) -> 3.5
A30: 29 | B30: Student | C30: 2-5 km | D30: Mixed | E30: 5 | F30: Cycles in summer, public transport in winter | G30: =INDEX('03_Commuting Assumptions'!$B$3:$B$7,MATCH(C30,'03_Commuting Assumptions'!$A$3:$A$7,0)) -> 3.5
A31: 30 | B31: Student | C31: 5-10 km | D31: Public transport | E31: 4 | G31: =INDEX('03_Commuting Assumptions'!$B$3:$B$7,MATCH(C31,'03_Commuting Assumptions'!$A$3:$A$7,0)) -> 7.5
A32: 31 | B32: Student | C32: <2 km | D32: Public transport | E32: 2 | G32: =INDEX('03_Commuting Assumptions'!$B$3:$B$7,MATCH(C32,'03_Commuting Assumptions'!$A$3:$A$7,0)) -> 1
A33: 32 | B33: Student | C33: 2-5 km | D33: Public transport | E33: 5 | G33: =INDEX('03_Commuting Assumptions'!$B$3:$B$7,MATCH(C33,'03_Commuting Assumptions'!$A$3:$A$7,0)) -> 3.5
A34: 33 | B34: Student | C34: 10-20 km | D34: Walk or cycle | E34: 4 | F34: Drives when raining heavily | G34: =INDEX('03_Commuting Assumptions'!$B$3:$B$7,MATCH(C34,'03_Commuting Assumptions'!$A$3:$A$7,0)) -> 15
A35: 34 | B35: Student | C35: 10-20 km | D35: Car share | E35: 3 | G35: =INDEX('03_Commuting Assumptions'!$B$3:$B$7,MATCH(C35,'03_Commuting Assumptions'!$A$3:$A$7,0)) -> 15
A36: 35 | B36: Student | C36: 2-5 km | D36: Public transport | E36: 3 | G36: =INDEX('03_Commuting Assumptions'!$B$3:$B$7,MATCH(C36,'03_Commuting Assumptions'!$A$3:$A$7,0)) -> 3.5
A37: 36 | B37: Student | C37: 5-10 km | D37: Public transport | E37: 4 | G37: =INDEX('03_Commuting Assumptions'!$B$3:$B$7,MATCH(C37,'03_Commuting Assumptions'!$A$3:$A$7,0)) -> 7.5
A38: 37 | B38: Student | C38: 2-5 km | D38: Walk or cycle | E38: 3 | F38: Drives when raining heavily | G38: =INDEX('03_Commuting Assumptions'!$B$3:$B$7,MATCH(C38,'03_Commuting Assumptions'!$A$3:$A$7,0)) -> 3.5
A39: 38 | B39: Student | C39: 10-20 km | D39: Car share | E39: 5 | G39: =INDEX('03_Commuting Assumptions'!$B$3:$B$7,MATCH(C39,'03_Commuting Assumptions'!$A$3:$A$7,0)) -> 15
A40: 39 | B40: Student | C40: <2 km | D40: Walk or cycle | E40: 5 | G40: =INDEX('03_Commuting Assumptions'!$B$3:$B$7,MATCH(C40,'03_Commuting Assumptions'!$A$3:$A$7,0)) -> 1
...

Sheet 03_Commuting Assumptions
A1: Distance-band lookup (km midpoint used for estimation)
A2: Band | B2: Midpoint one-way (km)
A3: <2 km | B3: 1
A4: 2-5 km | B4: 3.5
A5: 5-10 km | B5: 7.5
A6: 10-20 km | B6: 15
A7: >20 km | B7: 25
A10: Mode assumptions, derived from the survey (tab 02)
A11: Mode | B11: Respondents | C11: Mode share (%) | D11: Avg one-way km | E11: Avg days/week
A12: Walk or cycle | B12: =COUNTIF('02_Commuting Survey Responses'!$D$2:$D$61,A12) -> 20 | C12: =B12/60 -> 0.33333333 | D12: =IFERROR(AVERAGEIF('02_Commuting Survey Responses'!$D$2:$D$61,A12,'02_Commuting Survey Responses'!$G$2:$G$61),0) -> 5.95 | E12: =IFERROR(AVERAGEIF('02_Commuting Survey Responses'!$D$2:$D$61,A12,'02_Commuting Survey Responses'!$E$2:$E$61),0) -> 3.65
A13: Public transport | B13: =COUNTIF('02_Commuting Survey Responses'!$D$2:$D$61,A13) -> 14 | C13: =B13/60 -> 0.23333333 | D13: =IFERROR(AVERAGEIF('02_Commuting Survey Responses'!$D$2:$D$61,A13,'02_Commuting Survey Responses'!$G$2:$G$61),0) -> 4.6428571 | E13: =IFERROR(AVERAGEIF('02_Commuting Survey Responses'!$D$2:$D$61,A13,'02_Commuting Survey Responses'!$E$2:$E$61),0) -> 3.3571429
A14: Car (drive alone) | B14: =COUNTIF('02_Commuting Survey Responses'!$D$2:$D$61,A14) -> 11 | C14: =B14/60 -> 0.18333333 | D14: =IFERROR(AVERAGEIF('02_Commuting Survey Responses'!$D$2:$D$61,A14,'02_Commuting Survey Responses'!$G$2:$G$61),0) -> 9.4545455 | E14: =IFERROR(AVERAGEIF('02_Commuting Survey Responses'!$D$2:$D$61,A14,'02_Commuting Survey Responses'!$E$2:$E$61),0) -> 3.5454545
A15: Car share | B15: =COUNTIF('02_Commuting Survey Responses'!$D$2:$D$61,A15) -> 7 | C15: =B15/60 -> 0.11666667 | D15: =IFERROR(AVERAGEIF('02_Commuting Survey Responses'!$D$2:$D$61,A15,'02_Commuting Survey Responses'!$G$2:$G$61),0) -> 9.7142857 | E15: =IFERROR(AVERAGEIF('02_Commuting Survey Responses'!$D$2:$D$61,A15,'02_Commuting Survey Responses'!$E$2:$E$61),0) -> 3.8571429
A16: Mixed | B16: =COUNTIF('02_Commuting Survey Responses'!$D$2:$D$61,A16) -> 8 | C16: =B16/60 -> 0.13333333 | D16: =IFERROR(AVERAGEIF('02_Commuting Survey Responses'!$D$2:$D$61,A16,'02_Commuting Survey Responses'!$G$2:$G$61),0) -> 2.4375 | E16: =IFERROR(AVERAGEIF('02_Commuting Survey Responses'!$D$2:$D$61,A16,'02_Commuting Survey Responses'!$E$2:$E$61),0) -> 4.375
A19: Monthly km per person, by mode (round trip x avg days/week x 4.345 weeks/month)
A20: Mode | B20: Monthly km / person
A21: =A12 -> Walk or cycle | B21: =D12*2*E12*4.345 -> 188.72508
A22: =A13 -> Public transport | B22: =D13*2*E13*4.345 -> 135.44872
A23: =A14 -> Car (drive alone) | B23: =D14*2*E14*4.345 -> 291.29455
A24: =A15 -> Car share | B24: =D15*2*E15*4.345 -> 325.60898
A25: =A16 -> Mixed | B25: =D16*2*E16*4.345 -> 92.670703
A28: Note: "Walk or cycle" and "Mixed" are tracked for completeness but carry no direct emissions factor in this illustrative model (active travel = 0; "Mixed" is treated as non-motorised for screening purposes). Car share is scaled at 0.5 passengers-worth of car km per person to reflect shared occupancy.

Sheet 04_Business Trip Bookings (Raw)
A1: Destination distance lookup (one-way km from campus)
A2: Destination | B2: One-way km
A3: London | B3: 180
A4: Manchester | B4: 260
A5: Leeds | B5: 150
A6: Brussels | B6: 320
A7: Amsterdam | B7: 400
A8: Paris | B8: 900
A9: Berlin | B9: 950
A10: Zurich | B10: 780
A11: Edinburgh | B11: 650
A12: Dublin | B12: 700
A15: Trip ID | B15: Date | C15: Month | D15: Department | E15: Purpose | F15: Destination | G15: Mode | H15: Travellers | I15: One-way km | J15: Round-trip pax-km | K15: Hotel nights
A16: 1 | B16: 2026-01-26 | C16: Jan | D16: Estates | E16: Recruitment fair | F16: Berlin | G16: Air | H16: 1 | I16: =INDEX($B$3:$B$12,MATCH(F16,$A$3:$A$12,0)) -> 950 | J16: =I16*2*H16 -> 1900 | K16: 2
A17: 2 | B17: 2026-01-07 | C17: Jan | D17: Admin | E17: Conference | F17: Edinburgh | G17: Air | H17: 1 | I17: =INDEX($B$3:$B$12,MATCH(F17,$A$3:$A$12,0)) -> 650 | J17: =I17*2*H17 -> 1300 | K17: 2
A18: 3 | B18: 2026-01-11 | C18: Jan | D18: Research | E18: Site visit | F18: Dublin | G18: Rail | H18: 1 | I18: =INDEX($B$3:$B$12,MATCH(F18,$A$3:$A$12,0)) -> 700 | J18: =I18*2*H18 -> 1400 | K18: 1
A19: 4 | B19: 2026-01-06 | C19: Jan | D19: Engineering | E19: Conference | F19: Zurich | G19: Air | H19: 2 | I19: =INDEX($B$3:$B$12,MATCH(F19,$A$3:$A$12,0)) -> 780 | J19: =I19*2*H19 -> 3120 | K19: 1
A20: 5 | B20: 2026-01-08 | C20: Jan | D20: Engineering | E20: Partner meeting | F20: Leeds | G20: Rail | H20: 1 | I20: =INDEX($B$3:$B$12,MATCH(F20,$A$3:$A$12,0)) -> 150 | J20: =I20*2*H20 -> 300 | K20: 0
A21: 6 | B21: 2026-02-14 | C21: Feb | D21: Engineering | E21: Site visit | F21: Dublin | G21: Air | H21: 2 | I21: =INDEX($B$3:$B$12,MATCH(F21,$A$3:$A$12,0)) -> 700 | J21: =I21*2*H21 -> 2800 | K21: 3
A22: 7 | B22: 2026-02-23 | C22: Feb | D22: Admin | E22: Fieldwork | F22: Paris | G22: Rail | H22: 1 | I22: =INDEX($B$3:$B$12,MATCH(F22,$A$3:$A$12,0)) -> 900 | J22: =I22*2*H22 -> 1800 | K22: 2
A23: 8 | B23: 2026-02-15 | C23: Feb | D23: Research | E23: Conference | F23: Berlin | G23: Air | H23: 2 | I23: =INDEX($B$3:$B$12,MATCH(F23,$A$3:$A$12,0)) -> 950 | J23: =I23*2*H23 -> 3800 | K23: 2
A24: 9 | B24: 2026-02-04 | C24: Feb | D24: Engineering | E24: Partner meeting | F24: Zurich | G24: Air | H24: 1 | I24: =INDEX($B$3:$B$12,MATCH(F24,$A$3:$A$12,0)) -> 780 | J24: =I24*2*H24 -> 1560 | K24: 1
A25: 10 | B25: 2026-03-03 | C25: Mar | D25: Estates | E25: Fieldwork | F25: Edinburgh | G25: Air | H25: 3 | I25: =INDEX($B$3:$B$12,MATCH(F25,$A$3:$A$12,0)) -> 650 | J25: =I25*2*H25 -> 3900 | K25: 1
A26: 11 | B26: 2026-03-10 | C26: Mar | D26: Engineering | E26: Conference | F26: Leeds | G26: Car | H26: 1 | I26: =INDEX($B$3:$B$12,MATCH(F26,$A$3:$A$12,0)) -> 150 | J26: =I26*2*H26 -> 300 | K26: 0
A27: 12 | B27: 2026-03-05 | C27: Mar | D27: Research | E27: Conference | F27: Edinburgh | G27: Air | H27: 2 | I27: =INDEX($B$3:$B$12,MATCH(F27,$A$3:$A$12,0)) -> 650 | J27: =I27*2*H27 -> 2600 | K27: 2
... A75: 60 | B75: 2026-12-21 | C75: Dec | D75: Research | E75: Recruitment fair | F75: Berlin | G75: Air | H75: 1 | I75: =INDEX($B$3:$B$12,MATCH(F75,$A$3:$A$12,0)) -> 950 | J75: =I75*2*H75 -> 1900 | K75: 2
A77: n = 60 trips — illustrative synthetic booking export. Distance is looked up from destination, not typed per trip.

Sheet 05_Monthly Aggregation - Trips
A1: Month | B1: Flights (pax-km) | C1: Rail (pax-km) | D1: Car (pax-km) | E1: Hotel nights | F1: Trip count
A2: Jan | B2: =SUMIFS('04_Business Trip Bookings (Raw)'!$J$16:$J$75,'04_Business Trip Bookings (Raw)'!$C$16:$C$75,A2,'04_Business Trip Bookings (Raw)'!$G$16:$G$75,"Air") -> 6320 | C2: =SUMIFS('04_Business Trip Bookings (Raw)'!$J$16:$J$75,'04_Business Trip Bookings (Raw)'!$C$16:$C$75,A2,'04_Business Trip Bookings (Raw)'!$G$16:$G$75,"Rail") -> 1700 | D2: =SUMIFS('04_Business Trip Bookings (Raw)'!$J$16:$J$75,'04_Business Trip Bookings (Raw)'!$C$16:$C$75,A2,'04_Business Trip Bookings (Raw)'!$G$16:$G$75,"Car") -> 0 | E2: =SUMIFS('04_Business Trip Bookings (Raw)'!$K$16:$K$75,'04_Business Trip Bookings (Raw)'!$C$16:$C$75,A2) -> 6 | F2: =COUNTIFS('04_Business Trip Bookings (Raw)'!$C$16:$C$75,A2) -> 5
A3: Feb | B3: =SUMIFS('04_Business Trip Bookings (Raw)'!$J$16:$J$75,'04_Business Trip Bookings (Raw)'!$C$16:$C$75,A3,'04_Business Trip Bookings (Raw)'!$G$16:$G$75,"Air") -> 8160 | C3: =SUMIFS('04_Business Trip Bookings (Raw)'!$J$16:$J$75,'04_Business Trip Bookings (Raw)'!$C$16:$C$75,A3,'04_Business Trip Bookings (Raw)'!$G$16:$G$75,"Rail") -> 1800 | D3: =SUMIFS('04_Business Trip Bookings (Raw)'!$J$16:$J$75,'04_Business Trip Bookings (Raw)'!$C$16:$C$75,A3,'04_Business Trip Bookings (Raw)'!$G$16:$G$75,"Car") -> 0 | E3: =SUMIFS('04_Business Trip Bookings (Raw)'!$K$16:$K$75,'04_Business Trip Bookings (Raw)'!$C$16:$C$75,A3) -> 8 | F3: =COUNTIFS('04_Business Trip Bookings (Raw)'!$C$16:$C$75,A3) -> 4
A4: Mar | B4: =SUMIFS('04_Business Trip Bookings (Raw)'!$J$16:$J$75,'04_Business Trip Bookings (Raw)'!$C$16:$C$75,A4,'04_Business Trip Bookings (Raw)'!$G$16:$G$75,"Air") -> 12420 | C4: =SUMIFS('04_Business Trip Bookings (Raw)'!$J$16:$J$75,'04_Business Trip Bookings (Raw)'!$C$16:$C$75,A4,'04_Business Trip Bookings (Raw)'!$G$16:$G$75,"Rail") -> 0 | D4: =SUMIFS('04_Business Trip Bookings (Raw)'!$J$16:$J$75,'04_Business Trip Bookings (Raw)'!$C$16:$C$75,A4,'04_Business Trip Bookings (Raw)'!$G$16:$G$75,"Car") -> 300 | E4: =SUMIFS('04_Business Trip Bookings (Raw)'!$K$16:$K$75,'04_Business Trip Bookings (Raw)'!$C$16:$C$75,A4) -> 8 | F4: =COUNTIFS('04_Business Trip Bookings (Raw)'!$C$16:$C$75,A4) -> 6
A5: Apr | B5: =SUMIFS('04_Business Trip Bookings (Raw)'!$J$16:$J$75,'04_Business Trip Bookings (Raw)'!$C$16:$C$75,A5,'04_Business Trip Bookings (Raw)'!$G$16:$G$75,"Air") -> 0 | C5: =SUMIFS('04_Business Trip Bookings (Raw)'!$J$16:$J$75,'04_Business Trip Bookings (Raw)'!$C$16:$C$75,A5,'04_Business Trip Bookings (Raw)'!$G$16:$G$75,"Rail") -> 5420 | D5: =SUMIFS('04_Business Trip Bookings (Raw)'!$J$16:$J$75,'04_Business Trip Bookings (Raw)'!$C$16:$C$75,A5,'04_Business Trip Bookings (Raw)'!$G$16:$G$75,"Car") -> 960 | E5: =SUMIFS('04_Business Trip Bookings (Raw)'!$K$16:$K$75,'04_Business Trip Bookings (Raw)'!$C$16:$C$75,A5) -> 4 | F5: =COUNTIFS('04_Business Trip Bookings (Raw)'!$C$16:$C$75,A5) -> 5
A6: May | B6: =SUMIFS('04_Business Trip Bookings (Raw)'!$J$16:$J$75,'04_Business Trip Bookings (Raw)'!$C$16:$C$75,A6,'04_Business Trip Bookings (Raw)'!$G$16:$G$75,"Air") -> 7700 | C6: =SUMIFS('04_Business Trip Bookings (Raw)'!$J$16:$J$75,'04_Business Trip Bookings (Raw)'!$C$16:$C$75,A6,'04_Business Trip Bookings (Raw)'!$G$16:$G$75,"Rail") -> 5600 | D6: =SUMIFS('04_Business Trip Bookings (Raw)'!$J$16:$J$75,'04_Business Trip Bookings (Raw)'!$C$16:$C$75,A6,'04_Business Trip Bookings (Raw)'!$G$16:$G$75,"Car") -> 360 | E6: =SUMIFS('04_Business Trip Bookings (Raw)'!$K$16:$K$75,'04_Business Trip Bookings (Raw)'!$C$16:$C$75,A6) -> 10 | F6: =COUNTIFS('04_Business Trip Bookings (Raw)'!$C$16:$C$75,A6) -> 6
A7: Jun | B7: =SUMIFS('04_Business Trip Bookings (Raw)'!$J$16:$J$75,'04_Business Trip Bookings (Raw)'!$C$16:$C$75,A7,'04_Business Trip Bookings (Raw)'!$G$16:$G$75,"Air") -> 6600 | C7: =SUMIFS('04_Business Trip Bookings (Raw)'!$J$16:$J$75,'04_Business Trip Bookings (Raw)'!$C$16:$C$75,A7,'04_Business Trip Bookings (Raw)'!$G$16:$G$75,"Rail") -> 5420 | D7: =SUMIFS('04_Business Trip Bookings (Raw)'!$J$16:$J$75,'04_Business Trip Bookings (Raw)'!$C$16:$C$75,A7,'04_Business Trip Bookings (Raw)'!$G$16:$G$75,"Car") -> 1560 | E7: =SUMIFS('04_Business Trip Bookings (Raw)'!$K$16:$K$75,'04_Business Trip Bookings (Raw)'!$C$16:$C$75,A7) -> 10 | F7: =COUNTIFS('04_Business Trip Bookings (Raw)'!$C$16:$C$75,A7) -> 7
A8: Jul | B8: =SUMIFS('04_Business Trip Bookings (Raw)'!$J$16:$J$75,'04_Business Trip Bookings (Raw)'!$C$16:$C$75,A8,'04_Business Trip Bookings (Raw)'!$G$16:$G$75,"Air") -> 2600 | C8: =SUMIFS('04_Business Trip Bookings (Raw)'!$J$16:$J$75,'04_Business Trip Bookings (Raw)'!$C$16:$C$75,A8,'04_Business Trip Bookings (Raw)'!$G$16:$G$75,"Rail") -> 4680 | D8: =SUMIFS('04_Business Trip Bookings (Raw)'!$J$16:$J$75,'04_Business Trip Bookings (Raw)'!$C$16:$C$75,A8,'04_Business Trip Bookings (Raw)'!$G$16:$G$75,"Car") -> 0 | E8: =SUMIFS('04_Business Trip Bookings (Raw)'!$K$16:$K$75,'04_Business Trip Bookings (Raw)'!$C$16:$C$75,A8) -> 2 | F8: =COUNTIFS('04_Business Trip Bookings (Raw)'!$C$16:$C$75,A8) -> 2
A9: Aug | B9: =SUMIFS('04_Business Trip Bookings (Raw)'!$J$16:$J$75,'04_Business Trip Bookings (Raw)'!$C$16:$C$75,A9,'04_Business Trip Bookings (Raw)'!$G$16:$G$75,"Air") -> 0 | C9: =SUMIFS('04_Business Trip Bookings (Raw)'!$J$16:$J$75,'04_Business Trip Bookings (Raw)'!$C$16:$C$75,A9,'04_Business Trip Bookings (Raw)'!$G$16:$G$75,"Rail") -> 2540 | D9: =SUMIFS('04_Business Trip Bookings (Raw)'!$J$16:$J$75,'04_Business Trip Bookings (Raw)'!$C$16:$C$75,A9,'04_Business Trip Bookings (Raw)'!$G$16:$G$75,"Car") -> 0 | E9: =SUMIFS('04_Business Trip Bookings (Raw)'!$K$16:$K$75,'04_Business Trip Bookings (Raw)'!$C$16:$C$75,A9) -> 5 | F9: =COUNTIFS('04_Business Trip Bookings (Raw)'!$C$16:$C$75,A9) -> 2
A10: Sep | B10: =SUMIFS('04_Business Trip Bookings (Raw)'!$J$16:$J$75,'04_Business Trip Bookings (Raw)'!$C$16:$C$75,A10,'04_Business Trip Bookings (Raw)'!$G$16:$G$75,"Air") -> 6240 | C10: =SUMIFS('04_Business Trip Bookings (Raw)'!$J$16:$J$75,'04_Business Trip Bookings (Raw)'!$C$16:$C$75,A10,'04_Business Trip Bookings (Raw)'!$G$16:$G$75,"Rail") -> 1280 | D10: =SUMIFS('04_Business Trip Bookings (Raw)'!$J$16:$J$75,'04_Business Trip Bookings (Raw)'!$C$16:$C$75,A10,'04_Business Trip Bookings (Raw)'!$G$16:$G$75,"Car") -> 900 | E10: =SUMIFS('04_Business Trip Bookings (Raw)'!$K$16:$K$75,'04_Business Trip Bookings (Raw)'!$C$16:$C$75,A10) -> 9 | F10: =COUNTIFS('04_Business Trip Bookings (Raw)'!$C$16:$C$75,A10) -> 6
A11: Oct | B11: =SUMIFS('04_Business Trip Bookings (Raw)'!$J$16:$J$75,'04_Business Trip Bookings (Raw)'!$C$16:$C$75,A11,'04_Business Trip Bookings (Raw)'!$G$16:$G$75,"Air") -> 9060 | C11: =SUMIFS('04_Business Trip Bookings (Raw)'!$J$16:$J$75,'04_Business Trip Bookings (Raw)'!$C$16:$C$75,A11,'04_Business Trip Bookings (Raw)'!$G$16:$G$75,"Rail") -> 2960 | D11: =SUMIFS('04_Business Trip Bookings (Raw)'!$J$16:$J$75,'04_Business Trip Bookings (Raw)'!$C$16:$C$75,A11,'04_Business Trip Bookings (Raw)'!$G$16:$G$75,"Car") -> 300 | E11: =SUMIFS('04_Business Trip Bookings (Raw)'!$K$16:$K$75,'04_Business Trip Bookings (Raw)'!$C$16:$C$75,A11) -> 6 | F11: =COUNTIFS('04_Business Trip Bookings (Raw)'!$C$16:$C$75,A11) -> 6
A12: Nov | B12: =SUMIFS('04_Business Trip Bookings (Raw)'!$J$16:$J$75,'04_Business Trip Bookings (Raw)'!$C$16:$C$75,A12,'04_Business Trip Bookings (Raw)'!$G$16:$G$75,"Air") -> 1900 | C12: =SUMIFS('04_Business Trip Bookings (Raw)'!$J$16:$J$75,'04_Business Trip Bookings (Raw)'!$C$16:$C$75,A12,'04_Business Trip Bookings (Raw)'!$G$16:$G$75,"Rail") -> 2720 | D12: =SUMIFS('04_Business Trip Bookings (Raw)'!$J$16:$J$75,'04_Business Trip Bookings (Raw)'!$C$16:$C$75,A12,'04_Business Trip Bookings (Raw)'!$G$16:$G$75,"Car") -> 300 | E12: =SUMIFS('04_Business Trip Bookings (Raw)'!$K$16:$K$75,'04_Business Trip Bookings (Raw)'!$C$16:$C$75,A12) -> 5 | F12: =COUNTIFS('04_Business Trip Bookings (Raw)'!$C$16:$C$75,A12) -> 5
A13: Dec | B13: =SUMIFS('04_Business Trip Bookings (Raw)'!$J$16:$J$75,'04_Business Trip Bookings (Raw)'!$C$16:$C$75,A13,'04_Business Trip Bookings (Raw)'!$G$16:$G$75,"Air") -> 5020 | C13: =SUMIFS('04_Business Trip Bookings (Raw)'!$J$16:$J$75,'04_Business Trip Bookings (Raw)'!$C$16:$C$75,A13,'04_Business Trip Bookings (Raw)'!$G$16:$G$75,"Rail") -> 4700 | D13: =SUMIFS('04_Business Trip Bookings (Raw)'!$J$16:$J$75,'04_Business Trip Bookings (Raw)'!$C$16:$C$75,A13,'04_Business Trip Bookings (Raw)'!$G$16:$G$75,"Car") -> 660 | E13: =SUMIFS('04_Business Trip Bookings (Raw)'!$K$16:$K$75,'04_Business Trip Bookings (Raw)'!$C$16:$C$75,A13) -> 7 | F13: =COUNTIFS('04_Business Trip Bookings (Raw)'!$C$16:$C$75,A13) -> 6

Sheet 06_Monthly Estimate - Commuting
A1: Month | B1: Occupied FTE | C1: Car commuters (est.) | D1: Car km (monthly) | E1: Public transport commuters (est.) | F1: Public transport km (monthly)
A2: Jan | B2: 4200 | C2: =B2*'03_Commuting Assumptions'!$C$14 -> 770 | D2: =C2*'03_Commuting Assumptions'!$B$23 -> 224296.8 | E2: =B2*'03_Commuting Assumptions'!$C$13 -> 980 | F2: =E2*'03_Commuting Assumptions'!$B$22 -> 132739.75
A3: Feb | B3: 4200 | C3: =B3*'03_Commuting Assumptions'!$C$14 -> 770 | D3: =C3*'03_Commuting Assumptions'!$B$23 -> 224296.8 | E3: =B3*'03_Commuting Assumptions'!$C$13 -> 980 | F3: =E3*'03_Commuting Assumptions'!$B$22 -> 132739.75
A4: Mar | B4: 4100 | C4: =B4*'03_Commuting Assumptions'!$C$14 -> 751.66667 | D4: =C4*'03_Commuting Assumptions'!$B$23 -> 218956.4 | E4: =B4*'03_Commuting Assumptions'!$C$13 -> 956.66667 | F4: =E4*'03_Commuting Assumptions'!$B$22 -> 129579.28
A5: Apr | B5: 3900 | C5: =B5*'03_Commuting Assumptions'!$C$14 -> 715 | D5: =C5*'03_Commuting Assumptions'!$B$23 -> 208275.6 | E5: =B5*'03_Commuting Assumptions'!$C$13 -> 910 | F5: =E5*'03_Commuting Assumptions'!$B$22 -> 123258.34
A6: May | B6: 3500 | C6: =B6*'03_Commuting Assumptions'!$C$14 -> 641.66667 | D6: =C6*'03_Commuting Assumptions'!$B$23 -> 186914 | E6: =B6*'03_Commuting Assumptions'!$C$13 -> 816.66667 | F6: =E6*'03_Commuting Assumptions'!$B$22 -> 110616.46
A7: Jun | B7: 2500 | C7: =B7*'03_Commuting Assumptions'!$C$14 -> 458.33333 | D7: =C7*'03_Commuting Assumptions'!$B$23 -> 133510 | E7: =B7*'03_Commuting Assumptions'!$C$13 -> 583.33333 | F7: =E7*'03_Commuting Assumptions'!$B$22 -> 79011.756
A8: Jul | B8: 800 | C8: =B8*'03_Commuting Assumptions'!$C$14 -> 146.66667 | D8: =C8*'03_Commuting Assumptions'!$B$23 -> 42723.2 | E8: =B8*'03_Commuting Assumptions'!$C$13 -> 186.66667 | F8: =E8*'03_Commuting Assumptions'!$B$22 -> 25283.762
A9: Aug | B9: 600 | C9: =B9*'03_Commuting Assumptions'!$C$14 -> 110 | D9: =C9*'03_Commuting Assumptions'!$B$23 -> 32042.4 | E9: =B9*'03_Commuting Assumptions'!$C$13 -> 140 | F9: =E9*'03_Commuting Assumptions'!$B$22 -> 18962.821
A10: Sep | B10: 2800 | C10: =B10*'03_Commuting Assumptions'!$C$14 -> 513.33333 | D10: =C10*'03_Commuting Assumptions'!$B$23 -> 149531.2 | E10: =B10*'03_Commuting Assumptions'!$C$13 -> 653.33333 | F10: =E10*'03_Commuting Assumptions'!$B$22 -> 88493.167
A11: Oct | B11: 3800 | C11: =B11*'03_Commuting Assumptions'!$C$14 -> 696.66667 | D11: =C11*'03_Commuting Assumptions'!$B$23 -> 202935.2 | E11: =B11*'03_Commuting Assumptions'!$C$13 -> 886.66667 | F11: =E11*'03_Commuting Assumptions'!$B$22 -> 120097.87
A12: Nov | B12: 4100 | C12: =B12*'03_Commuting Assumptions'!$C$14 -> 751.66667 | D12: =C12*'03_Commuting Assumptions'!$B$23 -> 218956.4 | E12: =B12*'03_Commuting Assumptions'!$C$13 -> 956.66667 | F12: =E12*'03_Commuting Assumptions'!$B$22 -> 129579.28
A13: Dec | B13: 4300 | C13: =B13*'03_Commuting Assumptions'!$C$14 -> 788.33333 | D13: =C13*'03_Commuting Assumptions'!$B$23 -> 229637.2 | E13: =B13*'03_Commuting Assumptions'!$C$13 -> 1003.3333 | F13: =E13*'03_Commuting Assumptions'!$B$22 -> 135900.22
A15: Row references: 03_Commuting Assumptions row 13 = Public transport mode share; row 14 = Car (drive alone) mode share; row 22 = Public transport monthly km/person; row 23 = Car monthly km/person.

Sheet 07_Combined Travel Activity
A1: Month | B1: Business flights (pax-km) | C1: Business rail (pax-km) | D1: Business car (pax-km) | E1: Business hotel nights | F1: Commuting car (km) | G1: Commuting public transport (km)
A2: ='05_Monthly Aggregation - Trips'!A2 -> Jan | B2: ='05_Monthly Aggregation - Trips'!B2 -> 6320 | C2: ='05_Monthly Aggregation - Trips'!C2 -> 1700 | D2: ='05_Monthly Aggregation - Trips'!D2 -> 0 | E2: ='05_Monthly Aggregation - Trips'!E2 -> 6 | F2: ='06_Monthly Estimate - Commuting'!D2 -> 224296.8 | G2: ='06_Monthly Estimate - Commuting'!F2 -> 132739.75
A3: ='05_Monthly Aggregation - Trips'!A3 -> Feb | B3: ='05_Monthly Aggregation - Trips'!B3 -> 8160 | C3: ='05_Monthly Aggregation - Trips'!C3 -> 1800 | D3: ='05_Monthly Aggregation - Trips'!D3 -> 0 | E3: ='05_Monthly Aggregation - Trips'!E3 -> 8 | F3: ='06_Monthly Estimate - Commuting'!D3 -> 224296.8 | G3: ='06_Monthly Estimate - Commuting'!F3 -> 132739.75
A4: ='05_Monthly Aggregation - Trips'!A4 -> Mar | B4: ='05_Monthly Aggregation - Trips'!B4 -> 12420 | C4: ='05_Monthly Aggregation - Trips'!C4 -> 0 | D4: ='05_Monthly Aggregation - Trips'!D4 -> 300 | E4: ='05_Monthly Aggregation - Trips'!E4 -> 8 | F4: ='06_Monthly Estimate - Commuting'!D4 -> 218956.4 | G4: ='06_Monthly Estimate - Commuting'!F4 -> 129579.28
A5: ='05_Monthly Aggregation - Trips'!A5 -> Apr | B5: ='05_Monthly Aggregation - Trips'!B5 -> 0 | C5: ='05_Monthly Aggregation - Trips'!C5 -> 5420 | D5: ='05_Monthly Aggregation - Trips'!D5 -> 960 | E5: ='05_Monthly Aggregation - Trips'!E5 -> 4 | F5: ='06_Monthly Estimate - Commuting'!D5 -> 208275.6 | G5: ='06_Monthly Estimate - Commuting'!F5 -> 123258.34
A6: ='05_Monthly Aggregation - Trips'!A6 -> May | B6: ='05_Monthly Aggregation - Trips'!B6 -> 7700 | C6: ='05_Monthly Aggregation - Trips'!C6 -> 5600 | D6: ='05_Monthly Aggregation - Trips'!D6 -> 360 | E6: ='05_Monthly Aggregation - Trips'!E6 -> 10 | F6: ='06_Monthly Estimate - Commuting'!D6 -> 186914 | G6: ='06_Monthly Estimate - Commuting'!F6 -> 110616.46
A7: ='05_Monthly Aggregation - Trips'!A7 -> Jun | B7: ='05_Monthly Aggregation - Trips'!B7 -> 6600 | C7: ='05_Monthly Aggregation - Trips'!C7 -> 5420 | D7: ='05_Monthly Aggregation - Trips'!D7 -> 1560 | E7: ='05_Monthly Aggregation - Trips'!E7 -> 10 | F7: ='06_Monthly Estimate - Commuting'!D7 -> 133510 | G7: ='06_Monthly Estimate - Commuting'!F7 -> 79011.756
A8: ='05_Monthly Aggregation - Trips'!A8 -> Jul | B8: ='05_Monthly Aggregation - Trips'!B8 -> 2600 | C8: ='05_Monthly Aggregation - Trips'!C8 -> 4680 | D8: ='05_Monthly Aggregation - Trips'!D8 -> 0 | E8: ='05_Monthly Aggregation - Trips'!E8 -> 2 | F8: ='06_Monthly Estimate - Commuting'!D8 -> 42723.2 | G8: ='06_Monthly Estimate - Commuting'!F8 -> 25283.762
A9: ='05_Monthly Aggregation - Trips'!A9 -> Aug | B9: ='05_Monthly Aggregation - Trips'!B9 -> 0 | C9: ='05_Monthly Aggregation - Trips'!C9 -> 2540 | D9: ='05_Monthly Aggregation - Trips'!D9 -> 0 | E9: ='05_Monthly Aggregation - Trips'!E9 -> 5 | F9: ='06_Monthly Estimate - Commuting'!D9 -> 32042.4 | G9: ='06_Monthly Estimate - Commuting'!F9 -> 18962.821
A10: ='05_Monthly Aggregation - Trips'!A10 -> Sep | B10: ='05_Monthly Aggregation - Trips'!B10 -> 6240 | C10: ='05_Monthly Aggregation - Trips'!C10 -> 1280 | D10: ='05_Monthly Aggregation - Trips'!D10 -> 900 | E10: ='05_Monthly Aggregation - Trips'!E10 -> 9 | F10: ='06_Monthly Estimate - Commuting'!D10 -> 149531.2 | G10: ='06_Monthly Estimate - Commuting'!F10 -> 88493.167
A11: ='05_Monthly Aggregation - Trips'!A11 -> Oct | B11: ='05_Monthly Aggregation - Trips'!B11 -> 9060 | C11: ='05_Monthly Aggregation - Trips'!C11 -> 2960 | D11: ='05_Monthly Aggregation - Trips'!D11 -> 300 | E11: ='05_Monthly Aggregation - Trips'!E11 -> 6 | F11: ='06_Monthly Estimate - Commuting'!D11 -> 202935.2 | G11: ='06_Monthly Estimate - Commuting'!F11 -> 120097.87
A12: ='05_Monthly Aggregation - Trips'!A12 -> Nov | B12: ='05_Monthly Aggregation - Trips'!B12 -> 1900 | C12: ='05_Monthly Aggregation - Trips'!C12 -> 2720 | D12: ='05_Monthly Aggregation - Trips'!D12 -> 300 | E12: ='05_Monthly Aggregation - Trips'!E12 -> 5 | F12: ='06_Monthly Estimate - Commuting'!D12 -> 218956.4 | G12: ='06_Monthly Estimate - Commuting'!F12 -> 129579.28
A13: ='05_Monthly Aggregation - Trips'!A13 -> Dec | B13: ='05_Monthly Aggregation - Trips'!B13 -> 5020 | C13: ='05_Monthly Aggregation - Trips'!C13 -> 4700 | D13: ='05_Monthly Aggregation - Trips'!D13 -> 660 | E13: ='05_Monthly Aggregation - Trips'!E13 -> 7 | F13: ='06_Monthly Estimate - Commuting'!D13 -> 229637.2 | G13: ='06_Monthly Estimate - Commuting'!F13 -> 135900.22
A15: Same shape as the main travel-analysis workbook's 01_Raw Data tab, plus two new commuting columns — ready to carry emission factors below.

Sheet 08_Emission Factors
A1: Activity | B1: Unit | C1: Illustrative factor | D1: Notes
A2: Business air travel | B2: kgCO2e/passenger-km | C2: 0.18 | D2: Illustrative screening factor; no radiative-forcing uplift
A3: Business rail | B3: kgCO2e/passenger-km | C3: 0.04 | D3: Illustrative screening factor
A4: Business car | B4: kgCO2e/passenger-km | C4: 0.18 | D4: Illustrative screening factor
A5: Hotel | B5: kgCO2e/night | C5: 18 | D5: Illustrative screening factor
A6: Commuting car | B6: kgCO2e/km | C6: 0.17 | D6: Slightly below business-car factor to reflect typical commute vehicle mix
A7: Commuting public transport | B7: kgCO2e/km | C7: 0.05 | D7: Illustrative bus/rail blended factor
A8: Important | D8: Replace illustrative factors with the agreed methodology/source factors for real client work.

Sheet 09_KPIs & Dashboard
A1: University Travel — Commuting vs. Business Travel
A2: Illustrative management dashboard — synthetic data
A4: Month | B4: Business emissions (tCO2e) | C4: Commuting emissions (tCO2e) | D4: Total (tCO2e)
A5: ='07_Combined Travel Activity'!A2 -> Jan | B5: =('07_Combined Travel Activity'!B2*'08_Emission Factors'!$C$2+'07_Combined Travel Activity'!C2*'08_Emission Factors'!$C$3+'07_Combined Travel Activity'!D2*'08_Emission Factors'!$C$4+'07_Combined Travel Activity'!E2*'08_Emission Factors'!$C$5)/1000 -> 1.3136 | C5: =('07_Combined Travel Activity'!F2*'08_Emission Factors'!$C$6+'07_Combined Travel Activity'!G2*'08_Emission Factors'!$C$7)/1000 -> 44.767444 | D5: =B5+C5 -> 46.081044
A6: ='07_Combined Travel Activity'!A3 -> Feb | B6: =('07_Combined Travel Activity'!B3*'08_Emission Factors'!$C$2+'07_Combined Travel Activity'!C3*'08_Emission Factors'!$C$3+'07_Combined Travel Activity'!D3*'08_Emission Factors'!$C$4+'07_Combined Travel Activity'!E3*'08_Emission Factors'!$C$5)/1000 -> 1.6848 | C6: =('07_Combined Travel Activity'!F3*'08_Emission Factors'!$C$6+'07_Combined Travel Activity'!G3*'08_Emission Factors'!$C$7)/1000 -> 44.767444 | D6: =B6+C6 -> 46.452244
A7: ='07_Combined Travel Activity'!A4 -> Mar | B7: =('07_Combined Travel Activity'!B4*'08_Emission Factors'!$C$2+'07_Combined Travel Activity'!C4*'08_Emission Factors'!$C$3+'07_Combined Travel Activity'!D4*'08_Emission Factors'!$C$4+'07_Combined Travel Activity'!E4*'08_Emission Factors'!$C$5)/1000 -> 2.4336 | C7: =('07_Combined Travel Activity'!F4*'08_Emission Factors'!$C$6+'07_Combined Travel Activity'!G4*'08_Emission Factors'!$C$7)/1000 -> 43.701552 | D7: =B7+C7 -> 46.135152
A8: ='07_Combined Travel Activity'!A5 -> Apr | B8: =('07_Combined Travel Activity'!B5*'08_Emission Factors'!$C$2+'07_Combined Travel Activity'!C5*'08_Emission Factors'!$C$3+'07_Combined Travel Activity'!D5*'08_Emission Factors'!$C$4+'07_Combined Travel Activity'!E5*'08_Emission Factors'!$C$5)/1000 -> 0.4616 | C8: =('07_Combined Travel Activity'!F5*'08_Emission Factors'!$C$6+'07_Combined Travel Activity'!G5*'08_Emission Factors'!$C$7)/1000 -> 41.569769 | D8: =B8+C8 -> 42.031369
A9: ='07_Combined Travel Activity'!A6 -> May | B9: =('07_Combined Travel Activity'!B6*'08_Emission Factors'!$C$2+'07_Combined Travel Activity'!C6*'08_Emission Factors'!$C$3+'07_Combined Travel Activity'!D6*'08_Emission Factors'!$C$4+'07_Combined Travel Activity'!E6*'08_Emission Factors'!$C$5)/1000 -> 1.8548 | C9: =('07_Combined Travel Activity'!F6*'08_Emission Factors'!$C$6+'07_Combined Travel Activity'!G6*'08_Emission Factors'!$C$7)/1000 -> 37.306203 | D9: =B9+C9 -> 39.161003
A10: ='07_Combined Travel Activity'!A7 -> Jun | B10: =('07_Combined Travel Activity'!B7*'08_Emission Factors'!$C$2+'07_Combined Travel Activity'!C7*'08_Emission Factors'!$C$3+'07_Combined Travel Activity'!D7*'08_Emission Factors'!$C$4+'07_Combined Travel Activity'!E7*'08_Emission Factors'!$C$5)/1000 -> 1.8656 | C10: =('07_Combined Travel Activity'!F7*'08_Emission Factors'!$C$6+'07_Combined Travel Activity'!G7*'08_Emission Factors'!$C$7)/1000 -> 26.647288 | D10: =B10+C10 -> 28.512888
A11: ='07_Combined Travel Activity'!A8 -> Jul | B11: =('07_Combined Travel Activity'!B8*'08_Emission Factors'!$C$2+'07_Combined Travel Activity'!C8*'08_Emission Factors'!$C$3+'07_Combined Travel Activity'!D8*'08_Emission Factors'!$C$4+'07_Combined Travel Activity'!E8*'08_Emission Factors'!$C$5)/1000 -> 0.6912 | C11: =('07_Combined Travel Activity'!F8*'08_Emission Factors'!$C$6+'07_Combined Travel Activity'!G8*'08_Emission Factors'!$C$7)/1000 -> 8.5271321 | D11: =B11+C11 -> 9.2183321
A12: ='07_Combined Travel Activity'!A9 -> Aug | B12: =('07_Combined Travel Activity'!B9*'08_Emission Factors'!$C$2+'07_Combined Travel Activity'!C9*'08_Emission Factors'!$C$3+'07_Combined Travel Activity'!D9*'08_Emission Factors'!$C$4+'07_Combined Travel Activity'!E9*'08_Emission Factors'!$C$5)/1000 -> 0.1916 | C12: =('07_Combined Travel Activity'!F9*'08_Emission Factors'!$C$6+'07_Combined Travel Activity'!G9*'08_Emission Factors'!$C$7)/1000 -> 6.3953491 | D12: =B12+C12 -> 6.5869491
A13: ='07_Combined Travel Activity'!A10 -> Sep | B13: =('07_Combined Travel Activity'!B10*'08_Emission Factors'!$C$2+'07_Combined Travel Activity'!C10*'08_Emission Factors'!$C$3+'07_Combined Travel Activity'!D10*'08_Emission Factors'!$C$4+'07_Combined Travel Activity'!E10*'08_Emission Factors'!$C$5)/1000 -> 1.4984 | C13: =('07_Combined Travel Activity'!F10*'08_Emission Factors'!$C$6+'07_Combined Travel Activity'!G10*'08_Emission Factors'!$C$7)/1000 -> 29.844962 | D13: =B13+C13 -> 31.343362
A14: ='07_Combined Travel Activity'!A11 -> Oct | B14: =('07_Combined Travel Activity'!B11*'08_Emission Factors'!$C$2+'07_Combined Travel Activity'!C11*'08_Emission Factors'!$C$3+'07_Combined Travel Activity'!D11*'08_Emission Factors'!$C$4+'07_Combined Travel Activity'!E11*'08_Emission Factors'!$C$5)/1000 -> 1.9112 | C14: =('07_Combined Travel Activity'!F11*'08_Emission Factors'!$C$6+'07_Combined Travel Activity'!G11*'08_Emission Factors'!$C$7)/1000 -> 40.503877 | D14: =B14+C14 -> 42.415077
A15: ='07_Combined Travel Activity'!A12 -> Nov | B15: =('07_Combined Travel Activity'!B12*'08_Emission Factors'!$C$2+'07_Combined Travel Activity'!C12*'08_Emission Factors'!$C$3+'07_Combined Travel Activity'!D12*'08_Emission Factors'!$C$4+'07_Combined Travel Activity'!E12*'08_Emission Factors'!$C$5)/1000 -> 0.5948 | C15: =('07_Combined Travel Activity'!F12*'08_Emission Factors'!$C$6+'07_Combined Travel Activity'!G12*'08_Emission Factors'!$C$7)/1000 -> 43.701552 | D15: =B15+C15 -> 44.296352
A16: ='07_Combined Travel Activity'!A13 -> Dec | B16: =('07_Combined Travel Activity'!B13*'08_Emission Factors'!$C$2+'07_Combined Travel Activity'!C13*'08_Emission Factors'!$C$3+'07_Combined Travel Activity'!D13*'08_Emission Factors'!$C$4+'07_Combined Travel Activity'!E13*'08_Emission Factors'!$C$5)/1000 -> 1.3364 | C16: =('07_Combined Travel Activity'!F13*'08_Emission Factors'!$C$6+'07_Combined Travel Activity'!G13*'08_Emission Factors'!$C$7)/1000 -> 45.833335 | D16: =B16+C16 -> 47.169735
A19: ANNUAL BUSINESS-TRAVEL EMISSIONS (tCO2e) | C19: ANNUAL COMMUTING EMISSIONS (tCO2e) | E19: COMMUTING SHARE OF TOTAL | G19: TOTAL TRAVEL EMISSIONS (tCO2e)
A20: =SUM(B5:B16) -> 15.8376 | C20: =SUM(C5:C16) -> 413.56591 | E20: =SUM(C5:C16)/SUM(D5:D16) -> 0.96311721 | G20: =SUM(D5:D16) -> 429.40351
J24: Key insight
J25: ="Commuting accounts for "&TEXT(SUM(C5:C16)/SUM(D5:D16),"0.0%")&" of total travel emissions in this illustrative model — often the larger, less-visible category next to booked business travel." -> Commuting accounts for 96.3% of total travel emissions in this illustrative model — often the larger, less-visible category next to booked business travel.
A41: Recommendations
A42: • Repeat the commuting survey annually (or termly) to track mode shift, not just a one-off snapshot.
A43: • Validate the distance-band assumptions against postcode-level data if/when available, rather than self-reported bands alone.
A44: • Extend the questionnaire to capture EV/hybrid ownership if car-commuting emissions become a target for reduction.
A45: • Treat the business-trip Distance lookup table as living reference data — update it whenever a new regular destination appears.

Sheet 10_Chart - Biz Mode Share
H1: Mode | I1: Annual tCO2e
H2: Air | I2: =SUM('05_Monthly Aggregation - Trips'!B2:B13)*'08_Emission Factors'!$C$2/1000 -> 11.8836
H3: Rail | I3: =SUM('05_Monthly Aggregation - Trips'!C2:C13)*'08_Emission Factors'!$C$3/1000 -> 1.5528
H4: Car | I4: =SUM('05_Monthly Aggregation - Trips'!D2:D13)*'08_Emission Factors'!$C$4/1000 -> 0.9612
H5: Hotel | I5: =SUM('05_Monthly Aggregation - Trips'!E2:E13)*'08_Emission Factors'!$C$5/1000 -> 1.44

Sheet 11_Chart - Annual Biz v Commute
H1: Category | I1: tCO2e
H2: Business travel (booked) | I2: ='09_KPIs & Dashboard'!A20 -> 15.8376
H3: Commuting (surveyed) | I3: ='09_KPIs & Dashboard'!C20 -> 413.56591
